Workbook

Sheet Summary
A1: DPR inbound reconciliation - CPI payload vs PRD (ZPRA_T_DLY_PRD)
A3: Payload | B3: CallActivity_12 (DailyProductionSet, 16 records), REPORTING_DATE 06-10-2026 (COL_CPO: 07-10-2026)
A4: PRD extract | B4: ZPRA_T_DLY_PRD, production dates 05.10.2026 and 06.10.2026 as supplied by Arnav
A5: Compared | B5: Payload date vs PRD PRODUCTION_DATE, same asset/block/measure. 05.10 rows used only as previous-day reference.
A6: Prepared | B6: 08.10.2026
A8: By severity
A9: High | B9: =COUNTIF(Discrepancies!$J:$J,A9) -> 8
A10: Medium | B10: =COUNTIF(Discrepancies!$J:$J,A10) -> 9
A11: Low | B11: =COUNTIF(Discrepancies!$J:$J,A11) -> 6
A12: Total | B12: =SUM(B9:B11) -> 23
A14: By category
A15: Comment | B15: =COUNTIF(Discrepancies!$I:$I,A15) -> 3
A16: Date | B16: =COUNTIF(Discrepancies!$I:$I,A16) -> 1
A17: Master data / mapping | B17: =COUNTIF(Discrepancies!$I:$I,A17) -> 2
A18: Missing in PRD | B18: =COUNTIF(Discrepancies!$I:$I,A18) -> 3
A19: Missing in PRD / unit | B19: =COUNTIF(Discrepancies!$I:$I,A19) -> 2
A20: PRD only | B20: =COUNTIF(Discrepancies!$I:$I,A20) -> 1
A21: PRD value not in payload | B21: =COUNTIF(Discrepancies!$I:$I,A21) -> 5
A22: Rounding | B22: =COUNTIF(Discrepancies!$I:$I,A22) -> 1
A23: Scale x1,000 | B23: =COUNTIF(Discrepancies!$I:$I,A23) -> 2
A24: Scale x1,000 + block | B24: =COUNTIF(Discrepancies!$I:$I,A24) -> 1
A25: Scale x1,000 / locale | B25: =COUNTIF(Discrepancies!$I:$I,A25) -> 1
A26: Scale x1,000,000 | B26: =COUNTIF(Discrepancies!$I:$I,A26) -> 1
A28: Reconciliation lines
A29: Match | B29: =COUNTIF(Reconciliation!$I:$I,A29) -> 9
A30: OK - blank in payload, 0 in PRD | B30: =COUNTIF(Reconciliation!$I:$I,A30) -> 14
A31: All lines | B31: =COUNTA(Reconciliation!$I:$I)-1 -> 42

Sheet Discrepancies
A1: # | B1: Date | C1: Asset | D1: Block (payload) | E1: Measure | F1: Payload value | G1: PRD value | H1: PRD UoM | I1: Category | J1: Severity | K1: PRD - Payload | L1: PRD / Payload | M1: Observation | N1: Recommended action
A2: 1 | B2: 06.10.2026 | C2: BRA_BC1 | D2: BRA_BC1 | E2: NET_PROD | F2: 35006.289 | H2: BBL | I2: Missing in PRD | J2: High | K2: =IF(AND(ISNUMBER(F2),ISNUMBER(G2)),G2-F2,"") | L2: =IF(AND(ISNUMBER(F2),ISNUMBER(G2),F2<>0),G2/F2,"") | M2: No 06.10.2026 rows for BRA_BC1 in PRD. Payload sends the asset code as BLOCK; PRD books BRA_BC1 by block (ABALONA/ARGONAUTA/NAUTILUS/OSTRA, combined volume on ARGONAUTA - 05.10: 34,925 BBL). | N2: Confirm the 06.10 volume with Brazil asset team; agree whether CPI maps BLOCK=BRA_BC1 to BRA_BC1_ARGONAUTA.
A3: 2 | B3: 06.10.2026 | C3: BRA_BC1 | D3: BRA_BC1 | E3: GROSS_PROD | F3: 483753 | H3: MCM | I3: Missing in PRD / unit | J3: High | K3: =IF(AND(ISNUMBER(F3),ISNUMBER(G3)),G3-F3,"") | L3: =IF(AND(ISNUMBER(F3),ISNUMBER(G3),F3<>0),G3/F3,"") | M3: Missing in PRD. Payload 483,753 looks like m3; PRD unit for BRA_BC1 gas is MCM (05.10: 0.493). 483,753 m3 = 0.484 MCM - consistent with the day before. | N3: Fix unit at source or in CPI (divide by 1,000,000) before posting.
A4: 3 | B4: 06.10.2026 | C4: BRA_BC1 | D4: BRA_BC1 | E4: BLOCK | I4: Master data / mapping | J4: Medium | K4: =IF(AND(ISNUMBER(F4),ISNUMBER(G4)),G4-F4,"") | L4: =IF(AND(ISNUMBER(F4),ISNUMBER(G4),F4<>0),G4/F4,"") | M4: Block 'BRA_BC1' does not exist as a block in PRD. | N4: Add a CPI value mapping BRA_BC1 -> BRA_BC1_ARGONAUTA, or have the source send the block code.
A5: 4 | B5: 07.10.2026 | C5: COL_CPO | D5: COL_CPO_CALAO | E5: NET_PROD | F5: 22207.07 | H5: BBL | I5: Missing in PRD | J5: High | K5: =IF(AND(ISNUMBER(F5),ISNUMBER(G5)),G5-F5,"") | L5: =IF(AND(ISNUMBER(F5),ISNUMBER(G5),F5<>0),G5/F5,"") | M5: No 06.10 or 07.10 COL_CPO rows in the PRD extract. 22,207.07 is the asset total (05.10 split INDICO 20,288.56 + MARIPOSA 593.86 + PERICO 1,057.50 = 21,939.92) but is sent on block CALAO, which was 0 on 05.10. | N5: Confirm whether COL_CPO for this date was posted; correct block split (source or CPI).
A6: 5 | B6: 07.10.2026 | C6: COL_CPO | D6: COL_CPO_CALAO | E6: GROSS_PROD | F6: 188920 | H6: M3 | I6: Missing in PRD / unit | J6: High | K6: =IF(AND(ISNUMBER(F6),ISNUMBER(G6)),G6-F6,"") | L6: =IF(AND(ISNUMBER(F6),ISNUMBER(G6),F6<>0),G6/F6,"") | M6: Missing in PRD. 188,920 vs 05.10 PRD gas total 5,713.49 M3 (INDICO 4,042.23 + MARIPOSA 1,671.26) - about 33x, which suggests the payload is in cubic feet (1 m3 = 35.31 ft3). | N6: Confirm unit with Colombia asset; convert to M3 before posting.
A7: 6 | B7: 07.10.2026 | C7: COL_CPO | D7: COL_CPO_CALAO | E7: REPORTING_DATE | I7: Date | J7: Medium | K7: =IF(AND(ISNUMBER(F7),ISNUMBER(G7)),G7-F7,"") | L7: =IF(AND(ISNUMBER(F7),ISNUMBER(G7),F7<>0),G7/F7,"") | M7: REPORTING_DATE is 07-10-2026 while every other record in this batch is 06-10-2026. | N7: Check whether the source sent the report date instead of the production date for COL_CPO.
A8: 7 | B8: 06.10.2026 | C8: RUS_IEC | D8: RUS_IEC_DVOINOYE | E8: GROSS_PROD | F8: 0.66 | G8: 660 | H8: M3 | I8: Scale x1,000 | J8: Medium | K8: =IF(AND(ISNUMBER(F8),ISNUMBER(G8)),G8-F8,"") -> 659.34 | L8: =IF(AND(ISNUMBER(F8),ISNUMBER(G8),F8<>0),G8/F8,"") -> 1000 | M8: Payload 0.66, PRD 660 M3. Payload is in thousand m3; ZCL_ZPRA_DAILY_PROD_DPC_EXT applies no factor, so an interface posting would store 0.66 M3. | N8: Confirm intended unit; add x1000 conversion in CPI for RUS_IEC gas, or send M3.
A9: 8 | B9: 06.10.2026 | C9: RUS_IEC | D9: RUS_IEC_MAISKOYE | E9: GROSS_PROD | F9: 9.02 | G9: 9020 | H9: M3 | I9: Scale x1,000 + block | J9: Medium | K9: =IF(AND(ISNUMBER(F9),ISNUMBER(G9)),G9-F9,"") -> 9010.98 | L9: =IF(AND(ISNUMBER(F9),ISNUMBER(G9),F9<>0),G9/F9,"") -> 1000 | M9: Payload 9.02 on block MAISKOYE; PRD holds 9,020 M3 on block RUS_IEC_MAISKOYEGRP. Two differences: x1000 and block code. | N9: Add x1000 conversion and map MAISKOYE gas to MAISKOYEGRP (or align the source).
A10: 9 | B10: 06.10.2026 | C10: RUS_IEC | D10: RUS_IEC_SNEZHNOYE | E10: GROSS_PROD | F10: 234.469 | G10: 234469 | H10: M3 | I10: Scale x1,000 | J10: Medium | K10: =IF(AND(ISNUMBER(F10),ISNUMBER(G10)),G10-F10,"") -> 234234.53 | L10: =IF(AND(ISNUMBER(F10),ISNUMBER(G10),F10<>0),G10/F10,"") -> 1000 | M10: Payload 234.469, PRD 234,469 M3 (thousand m3 vs m3). | N10: As DVOINOYE.
A11: 10 | B11: 06.10.2026 | C11: RUS_IEC | D11: RUS_IEC_EASTMAISKOYE | E11: BLOCK | I11: Master data / mapping | J11: Low | K11: =IF(AND(ISNUMBER(F11),ISNUMBER(G11)),G11-F11,"") | L11: =IF(AND(ISNUMBER(F11),ISNUMBER(G11),F11<>0),G11/F11,"") | M11: Block sent in payload (all measures blank) - no such block in PRD. | N11: Confirm whether EASTMAISKOYE should be maintained; harmless while blank.
A12: 11 | B12: 06.10.2026 | C12: RUS_IEC | D12: RUS_IEC_KIEVEGANSKOY | E12: BLOCK | G12: 0 | I12: PRD only | J12: Low | K12: =IF(AND(ISNUMBER(F12),ISNUMBER(G12)),G12-F12,"") | L12: =IF(AND(ISNUMBER(F12),ISNUMBER(G12),F12<>0),G12/F12,"") | M12: PRD has NET_PROD / WATER_INJ / GROSS_PROD = 0 for this block; block is not in the payload. | N12: Information only.
A13: 12 | B13: 06.10.2026 | C13: RUS_VAN | D13: RUS_VAN_VANKORNEFT | E13: NET_PROD | F13: 146657.28 | G13: 146657.3 | H13: BBL | I13: Rounding | J13: Low | K13: =IF(AND(ISNUMBER(F13),ISNUMBER(G13)),G13-F13,"") -> 0.02 | L13: =IF(AND(ISNUMBER(F13),ISNUMBER(G13),F13<>0),G13/F13,"") -> 1.0000001 | M13: PRD 146,657.30 vs payload 146,657.28 (+0.02) - PRD value rounded to one decimal. | N13: Information only, unless PRD must hold full precision.
A14: 13 | B14: 06.10.2026 | C14: RUS_VAN | D14: RUS_VAN_VANKORNEFT | E14: GROSS_PROD | F14: 10.735 | G14: 10735000 | H14: M3 | I14: Scale x1,000,000 | J14: Medium | K14: =IF(AND(ISNUMBER(F14),ISNUMBER(G14)),G14-F14,"") -> 10734989 | L14: =IF(AND(ISNUMBER(F14),ISNUMBER(G14),F14<>0),G14/F14,"") -> 1000000 | M14: Payload 10.735 (million m3), PRD 10,735,000 M3. | N14: Add x1,000,000 conversion in CPI for RUS_VAN gas, or send M3.
A15: 14 | B15: 06.10.2026 | C15: RUS_VAN | D15: RUS_VAN_VANKORNEFT | E15: WATER_INJ | G15: 282033 | H15: M3 | I15: PRD value not in payload | J15: High | K15: =IF(AND(ISNUMBER(F15),ISNUMBER(G15)),G15-F15,"") | L15: =IF(AND(ISNUMBER(F15),ISNUMBER(G15),F15<>0),G15/F15,"") | M15: PRD holds WATER_INJ 282,033 M3; payload WATER_INJ is blank. | N15: Confirm source of 282,033 and why it is not in the CPI message.
A16: 15 | B16: 06.10.2026 | C16: RUS_VAN | D16: RUS_VAN_VANKORNEFT | E16: COMMENT | I16: Comment | J16: Low | K16: =IF(AND(ISNUMBER(F16),ISNUMBER(G16)),G16-F16,"") | L16: =IF(AND(ISNUMBER(F16),ISNUMBER(G16),F16<>0),G16/F16,"") | M16: Payload COMMENT is exactly 1,000 characters and cut mid-word ("...oil-gathering pip"); PRD comment is blank. | N16: Check COMMENT length limit at source/CPI and in ZPRA_T_DLY_PRD-COMMENTS.
A17: 16 | B17: 06.10.2026 | C17: SSU_SPO | D17: SSU_SPO_BLOCK5A | E17: NET_PROD | F17: 15217.455 | H17: BBL | I17: Missing in PRD | J17: High | K17: =IF(AND(ISNUMBER(F17),ISNUMBER(G17)),G17-F17,"") | L17: =IF(AND(ISNUMBER(F17),ISNUMBER(G17),F17<>0),G17/F17,"") | M17: No 06.10 SSU_SPO row in PRD. Payload 15,217.455 is +28% on 05.10 (11,869.00). | N17: Confirm volume with South Sudan asset and post.
A18: 17 | B18: 06.10.2026 | C18: VEN_CAR | D18: VEN_CAR_CARABOBO | E18: NET_PROD | F18: 7.105 | G18: 7105 | H18: BBL | I18: Scale x1,000 / locale | J18: High | K18: =IF(AND(ISNUMBER(F18),ISNUMBER(G18)),G18-F18,"") -> 7097.895 | L18: =IF(AND(ISNUMBER(F18),ISNUMBER(G18),F18<>0),G18/F18,"") -> 1000 | M18: Payload '7.105' is Spanish thousands notation for 7,105 (05.10 PRD: 7,110). The interface strips only commas, so it would post 7.105 BBL. | N18: Source/CPI must send plain decimal numbers (no thousands separator).
A19: 18 | B19: 06.10.2026 | C19: VEN_CAR | D19: VEN_CAR_CARABOBO | E19: GAS_FLARE | G19: 6.67 | H19: MCF | I19: PRD value not in payload | J19: Medium | K19: =IF(AND(ISNUMBER(F19),ISNUMBER(G19)),G19-F19,"") | L19: =IF(AND(ISNUMBER(F19),ISNUMBER(G19),F19<>0),G19/F19,"") | M19: PRD GAS_FLARE 6.67 MCF; payload blank. | N19: Add GAS_FLARE to the source extract.
A20: 19 | B20: 06.10.2026 | C20: VEN_CAR | D20: VEN_CAR_CARABOBO | E20: INT_CONS | G20: 0.2 | H20: MCF | I20: PRD value not in payload | J20: Medium | K20: =IF(AND(ISNUMBER(F20),ISNUMBER(G20)),G20-F20,"") | L20: =IF(AND(ISNUMBER(F20),ISNUMBER(G20),F20<>0),G20/F20,"") | M20: PRD INT_CONS 0.2 MCF; payload blank (6.67 + 0.2 = 6.87 = GROSS_PROD). | N20: Add INT_CONS to the source extract.
A21: 20 | B21: 06.10.2026 | C21: VEN_CAR | D21: VEN_CAR_CARABOBO | E21: COMMENT | I21: Comment | J21: Low | K21: =IF(AND(ISNUMBER(F21),ISNUMBER(G21)),G21-F21,"") | L21: =IF(AND(ISNUMBER(F21),ISNUMBER(G21),F21<>0),G21/F21,"") | M21: Payload carries a comment; PRD comment is blank. | N21: Information only.
A22: 21 | B22: 06.10.2026 | C22: VEN_SAN | D22: VEN_SAN_PIVSA | E22: NET_PROD | G22: 5550 | H22: BBL | I22: PRD value not in payload | J22: High | K22: =IF(AND(ISNUMBER(F22),ISNUMBER(G22)),G22-F22,"") | L22: =IF(AND(ISNUMBER(F22),ISNUMBER(G22),F22<>0),G22/F22,"") | M22: PRD NET_PROD 5,550 BBL; payload NET_PROD is blank. Payload comment contains '5575' (TOTAL POZOS PIVSA) - not 5,550. | N22: Confirm correct volume with Venezuela asset; fix source extract for NET_PROD.
A23: 22 | B23: 06.10.2026 | C23: VEN_SAN | D23: VEN_SAN_PIVSA | E23: GAS_FLARE | G23: 3.75 | H23: MCF | I23: PRD value not in payload | J23: Medium | K23: =IF(AND(ISNUMBER(F23),ISNUMBER(G23)),G23-F23,"") | L23: =IF(AND(ISNUMBER(F23),ISNUMBER(G23),F23<>0),G23/F23,"") | M23: PRD GAS_FLARE 3.75 MCF; payload blank. | N23: Add GAS_FLARE to the source extract.
A24: 23 | B24: 06.10.2026 | C24: VEN_SAN | D24: VEN_SAN_PIVSA | E24: COMMENT | I24: Comment | J24: Low | K24: =IF(AND(ISNUMBER(F24),ISNUMBER(G24)),G24-F24,"") | L24: =IF(AND(ISNUMBER(F24),ISNUMBER(G24),F24<>0),G24/F24,"") | M24: Payload comment is a flattened well-status table; PRD comment is blank. | N24: Information only.

Sheet Reconciliation
A1: Date | B1: Asset | C1: Block (payload) | D1: Measure | E1: Payload value | F1: Block (PRD) | G1: PRD UoM | H1: PRD value | I1: Status | J1: PRD - Payload
A2: 06.10.2026 | B2: MMR_BA1 | C2: MMR_BA1_BLOCKA1 | D2: GROSS_PROD | E2: 374.52 | F2: MMR_BA1_BLOCKA1 | G2: MCF | H2: 374.52 | I2: Match | J2: =IF(AND(ISNUMBER(E2),ISNUMBER(H2)),H2-E2,"") -> 0
A3: 06.10.2026 | B3: MMR_BA3 | C3: MMR_BA3_BLOCKA3 | D3: GROSS_PROD | E3: 107.853 | F3: MMR_BA3_BLOCKA3 | G3: MCF | H3: 107.853 | I3: Match | J3: =IF(AND(ISNUMBER(E3),ISNUMBER(H3)),H3-E3,"") -> 0
A4: 06.10.2026 | B4: BRA_BC1 | C4: BRA_BC1 | D4: NET_PROD | E4: 35006.289 | I4: Missing in PRD | J4: =IF(AND(ISNUMBER(E4),ISNUMBER(H4)),H4-E4,"")
A5: 06.10.2026 | B5: BRA_BC1 | C5: BRA_BC1 | D5: GROSS_PROD | E5: 483753 | I5: Missing in PRD | J5: =IF(AND(ISNUMBER(E5),ISNUMBER(H5)),H5-E5,"")
A6: 07.10.2026 | B6: COL_CPO | C6: COL_CPO_CALAO | D6: NET_PROD | E6: 22207.07 | I6: Missing in PRD | J6: =IF(AND(ISNUMBER(E6),ISNUMBER(H6)),H6-E6,"")
A7: 07.10.2026 | B7: COL_CPO | C7: COL_CPO_CALAO | D7: GROSS_PROD | E7: 188920 | I7: Missing in PRD | J7: =IF(AND(ISNUMBER(E7),ISNUMBER(H7)),H7-E7,"")
A8: 06.10.2026 | B8: RUS_IEC | C8: RUS_IEC_DVOINOYE | D8: NET_PROD | E8: 82 | F8: RUS_IEC_DVOINOYE | G8: BBL | H8: 82 | I8: Match | J8: =IF(AND(ISNUMBER(E8),ISNUMBER(H8)),H8-E8,"") -> 0
A9: 06.10.2026 | B9: RUS_IEC | C9: RUS_IEC_DVOINOYE | D9: WATER_INJ | F9: RUS_IEC_DVOINOYE | G9: BBL | H9: 0 | I9: OK - blank in payload, 0 in PRD | J9: =IF(AND(ISNUMBER(E9),ISNUMBER(H9)),H9-E9,"")
A10: 06.10.2026 | B10: RUS_IEC | C10: RUS_IEC_DVOINOYE | D10: GROSS_PROD | E10: 0.66 | F10: RUS_IEC_DVOINOYE | G10: M3 | H10: 660 | I10: Scale x1,000 | J10: =IF(AND(ISNUMBER(E10),ISNUMBER(H10)),H10-E10,"") -> 659.34
A11: 06.10.2026 | B11: RUS_IEC | C11: RUS_IEC_FESTIVALNOYE | D11: NET_PROD | F11: RUS_IEC_FESTIVALNOYE | G11: BBL | H11: 0 | I11: OK - blank in payload, 0 in PRD | J11: =IF(AND(ISNUMBER(E11),ISNUMBER(H11)),H11-E11,"")
A12: 06.10.2026 | B12: RUS_IEC | C12: RUS_IEC_FESTIVALNOYE | D12: WATER_INJ | F12: RUS_IEC_FESTIVALNOYE | G12: BBL | H12: 0 | I12: OK - blank in payload, 0 in PRD | J12: =IF(AND(ISNUMBER(E12),ISNUMBER(H12)),H12-E12,"")
A13: 06.10.2026 | B13: RUS_IEC | C13: RUS_IEC_FESTIVALNOYE | D13: GROSS_PROD | F13: RUS_IEC_FESTIVALNOYE | G13: M3 | H13: 0 | I13: OK - blank in payload, 0 in PRD | J13: =IF(AND(ISNUMBER(E13),ISNUMBER(H13)),H13-E13,"")
A14: 06.10.2026 | B14: RUS_IEC | C14: RUS_IEC_MAISKOYE | D14: NET_PROD | E14: 267 | F14: RUS_IEC_MAISKOYE | G14: BBL | H14: 267 | I14: Match | J14: =IF(AND(ISNUMBER(E14),ISNUMBER(H14)),H14-E14,"") -> 0
A15: 06.10.2026 | B15: RUS_IEC | C15: RUS_IEC_MAISKOYE | D15: WATER_INJ | F15: RUS_IEC_MAISKOYE | G15: BBL | H15: 0 | I15: OK - blank in payload, 0 in PRD | J15: =IF(AND(ISNUMBER(E15),ISNUMBER(H15)),H15-E15,"")
A16: 06.10.2026 | B16: RUS_IEC | C16: RUS_IEC_MAISKOYE | D16: GROSS_PROD | E16: 9.02 | F16: RUS_IEC_MAISKOYEGRP | G16: M3 | H16: 9020 | I16: Scale x1,000 (PRD block RUS_IEC_MAISKOYEGRP) | J16: =IF(AND(ISNUMBER(E16),ISNUMBER(H16)),H16-E16,"") -> 9010.98
A17: 06.10.2026 | B17: RUS_IEC | C17: RUS_IEC_MIDMAISKOYE | D17: NET_PROD | F17: RUS_IEC_MIDMAISKOYE | G17: BBL | H17: 0 | I17: OK - blank in payload, 0 in PRD | J17: =IF(AND(ISNUMBER(E17),ISNUMBER(H17)),H17-E17,"")
A18: 06.10.2026 | B18: RUS_IEC | C18: RUS_IEC_MIDMAISKOYE | D18: WATER_INJ | F18: RUS_IEC_MIDMAISKOYE | G18: BBL | H18: 0 | I18: OK - blank in payload, 0 in PRD | J18: =IF(AND(ISNUMBER(E18),ISNUMBER(H18)),H18-E18,"")
A19: 06.10.2026 | B19: RUS_IEC | C19: RUS_IEC_SNEZHNOYE | D19: NET_PROD | E19: 904 | F19: RUS_IEC_SNEZHNOYE | G19: BBL | H19: 904 | I19: Match | J19: =IF(AND(ISNUMBER(E19),ISNUMBER(H19)),H19-E19,"") -> 0
A20: 06.10.2026 | B20: RUS_IEC | C20: RUS_IEC_SNEZHNOYE | D20: WATER_INJ | F20: RUS_IEC_SNEZHNOYE | G20: BBL | H20: 0 | I20: OK - blank in payload, 0 in PRD | J20: =IF(AND(ISNUMBER(E20),ISNUMBER(H20)),H20-E20,"")
A21: 06.10.2026 | B21: RUS_IEC | C21: RUS_IEC_SNEZHNOYE | D21: GROSS_PROD | E21: 234.469 | F21: RUS_IEC_SNEZHNOYE | G21: M3 | H21: 234469 | I21: Scale x1,000 | J21: =IF(AND(ISNUMBER(E21),ISNUMBER(H21)),H21-E21,"") -> 234234.53
A22: 06.10.2026 | B22: RUS_IEC | C22: RUS_IEC_SOUTHMAISKOY | D22: NET_PROD | E22: 553 | F22: RUS_IEC_SOUTHMAISKOY | G22: BBL | H22: 553 | I22: Match | J22: =IF(AND(ISNUMBER(E22),ISNUMBER(H22)),H22-E22,"") -> 0
A23: 06.10.2026 | B23: RUS_IEC | C23: RUS_IEC_SOUTHMAISKOY | D23: WATER_INJ | F23: RUS_IEC_SOUTHMAISKOY | G23: BBL | H23: 0 | I23: OK - blank in payload, 0 in PRD | J23: =IF(AND(ISNUMBER(E23),ISNUMBER(H23)),H23-E23,"")
A24: 06.10.2026 | B24: RUS_IEC | C24: RUS_IEC_WESTMAISKOYE | D24: NET_PROD | F24: RUS_IEC_WESTMAISKOYE | G24: BBL | H24: 0 | I24: OK - blank in payload, 0 in PRD | J24: =IF(AND(ISNUMBER(E24),ISNUMBER(H24)),H24-E24,"")
A25: 06.10.2026 | B25: RUS_IEC | C25: RUS_IEC_WESTMAISKOYE | D25: WATER_INJ | F25: RUS_IEC_WESTMAISKOYE | G25: BBL | H25: 0 | I25: OK - blank in payload, 0 in PRD | J25: =IF(AND(ISNUMBER(E25),ISNUMBER(H25)),H25-E25,"")
A26: 06.10.2026 | B26: UAE_LZC | C26: UAE_LZC_LOWERZAKUM | D26: NET_PROD | E26: 450020 | F26: UAE_LZC_LOWERZAKUM | G26: BBL | H26: 450020 | I26: Match | J26: =IF(AND(ISNUMBER(E26),ISNUMBER(H26)),H26-E26,"") -> 0
A27: 06.10.2026 | B27: VEN_CAR | C27: VEN_CAR_CARABOBO | D27: NET_PROD | E27: 7.105 | F27: VEN_CAR_CARABOBO | G27: BBL | H27: 7105 | I27: Scale x1,000 | J27: =IF(AND(ISNUMBER(E27),ISNUMBER(H27)),H27-E27,"") -> 7097.895
A28: 06.10.2026 | B28: VEN_CAR | C28: VEN_CAR_CARABOBO | D28: GROSS_PROD | E28: 6.87 | F28: VEN_CAR_CARABOBO | G28: MCF | H28: 6.87 | I28: Match | J28: =IF(AND(ISNUMBER(E28),ISNUMBER(H28)),H28-E28,"") -> 0
A29: 06.10.2026 | B29: VEN_CAR | C29: VEN_CAR_CARABOBO | D29: GAS_FLARE | F29: VEN_CAR_CARABOBO | G29: MCF | H29: 6.67 | I29: PRD value not in payload | J29: =IF(AND(ISNUMBER(E29),ISNUMBER(H29)),H29-E29,"")
A30: 06.10.2026 | B30: VEN_CAR | C30: VEN_CAR_CARABOBO | D30: INT_CONS | F30: VEN_CAR_CARABOBO | G30: MCF | H30: 0.2 | I30: PRD value not in payload | J30: =IF(AND(ISNUMBER(E30),ISNUMBER(H30)),H30-E30,"")
A31: 06.10.2026 | B31: VEN_SAN | C31: VEN_SAN_PIVSA | D31: NET_PROD | F31: VEN_SAN_PIVSA | G31: BBL | H31: 5550 | I31: PRD value not in payload | J31: =IF(AND(ISNUMBER(E31),ISNUMBER(H31)),H31-E31,"")
A32: 06.10.2026 | B32: VEN_SAN | C32: VEN_SAN_PIVSA | D32: WATER_INJ | F32: VEN_SAN_PIVSA | G32: BBL | H32: 0 | I32: OK - blank in payload, 0 in PRD | J32: =IF(AND(ISNUMBER(E32),ISNUMBER(H32)),H32-E32,"")
A33: 06.10.2026 | B33: VEN_SAN | C33: VEN_SAN_PIVSA | D33: GROSS_PROD | E33: 3.75 | F33: VEN_SAN_PIVSA | G33: MCF | H33: 3.75 | I33: Match | J33: =IF(AND(ISNUMBER(E33),ISNUMBER(H33)),H33-E33,"") -> 0
A34: 06.10.2026 | B34: VEN_SAN | C34: VEN_SAN_PIVSA | D34: GAS_FLARE | F34: VEN_SAN_PIVSA | G34: MCF | H34: 3.75 | I34: PRD value not in payload | J34: =IF(AND(ISNUMBER(E34),ISNUMBER(H34)),H34-E34,"")
A35: 06.10.2026 | B35: VEN_SAN | C35: VEN_SAN_PIVSA | D35: INT_CONS | F35: VEN_SAN_PIVSA | G35: MCF | H35: 0 | I35: OK - blank in payload, 0 in PRD | J35: =IF(AND(ISNUMBER(E35),ISNUMBER(H35)),H35-E35,"")
A36: 06.10.2026 | B36: SSU_SPO | C36: SSU_SPO_BLOCK5A | D36: NET_PROD | E36: 15217.455 | I36: Missing in PRD | J36: =IF(AND(ISNUMBER(E36),ISNUMBER(H36)),H36-E36,"")
A37: 06.10.2026 | B37: RUS_VAN | C37: RUS_VAN_VANKORNEFT | D37: NET_PROD | E37: 146657.28 | F37: RUS_VAN_VANKORNEFT | G37: BBL | H37: 146657.3 | I37: Rounding | J37: =IF(AND(ISNUMBER(E37),ISNUMBER(H37)),H37-E37,"") -> 0.02
A38: 06.10.2026 | B38: RUS_VAN | C38: RUS_VAN_VANKORNEFT | D38: WATER_INJ | F38: RUS_VAN_VANKORNEFT | G38: M3 | H38: 282033 | I38: PRD value not in payload | J38: =IF(AND(ISNUMBER(E38),ISNUMBER(H38)),H38-E38,"")
A39: 06.10.2026 | B39: RUS_VAN | C39: RUS_VAN_VANKORNEFT | D39: GAS_INJ | F39: RUS_VAN_VANKORNEFT | G39: M3 | H39: 0 | I39: OK - blank in payload, 0 in PRD | J39: =IF(AND(ISNUMBER(E39),ISNUMBER(H39)),H39-E39,"")
A40: 06.10.2026 | B40: RUS_VAN | C40: RUS_VAN_VANKORNEFT | D40: GROSS_PROD | E40: 10.735 | F40: RUS_VAN_VANKORNEFT | G40: M3 | H40: 10735000 | I40: Scale x1,000,000 | J40: =IF(AND(ISNUMBER(E40),ISNUMBER(H40)),H40-E40,"") -> 10734989
...

Sheet Interface notes
A1: # | B1: Finding (ZCL_ZPRA_DAILY_PROD_DPC_EXT / CPI) | C1: Impact
A2: 1 | B2: REPORTING_DATE arrives as DD-MM-YYYY ('06-10-2026'). BUILD_PROD_ROWS converts only when the value contains '.'; otherwise it moves the text straight into a DATS field ('06-10-20'), DATE_CHECK_PLAUSIBILITY fails and the record is rejected. | C2: If CPI forwards this date as-is, every record in this batch is rejected - none of the 06.10 PRD rows would come from this message. Check /IWFND/ERROR_LOG and the CPI message log for this run.
A3: 2 | B3: PRD has 0-value rows (e.g. RUS_IEC WATER_INJ, VEN_SAN INT_CONS) where the payload is blank. The class skips blank fields, and after the 06/10/26 fix it skips zero values too. | C3: These rows did not come from the interface. CREATED_BY values (95660, 96029, 60749, ...) suggest manual / per-asset entry.
A4: 3 | B4: The class stores the payload number as-is with the UoM from GET_PROD_UOM - no scaling. | C4: The x1,000 / x1,000,000 differences (RUS_IEC, RUS_VAN, BRA_BC1 gas) would post wrong quantities through the interface. Units must be fixed in CPI or at source.
A5: 4 | B5: The class strips commas only. A value like '7.105' (Spanish thousands separator) is read as 7.105. | C5: VEN_CAR NET_PROD would post as 7.105 BBL instead of 7,105.
A6: 5 | B6: Block codes in the payload that PRD does not use: BRA_BC1 (asset code), RUS_IEC_EASTMAISKOYE, and RUS_IEC_MAISKOYE gas (PRD: MAISKOYEGRP). COL_CPO sends the asset total on block CALAO. | C6: The class does not validate the block, so these would post to blocks the DPR reports do not use.
A7: 6 | B7: RUS_VAN COMMENT is exactly 1,000 characters - cut off at source or in CPI. | C7: Remark text lost; confirm the length of ZPRA_T_DLY_PRD-COMMENTS.
